Workbook
Name ExpoArt: 'Price List SE'!$A$1:$D$33451

Sheet Product search
A1: Product code | B1: Description | C1: EUR/PC | D1: MOQ
B2: =IFERROR(VLOOKUP(A2,'Price List SE'!$A$2:$D$93217,2,0),"Enter product code") -> Enter product code | C2: =IFERROR(VLOOKUP(A2,'Price List SE'!$A$2:$D$88096,3,0),"") | D2: =IFERROR(VLOOKUP(A2,'Price List SE'!$A$2:$D$93217,4,0),"")
B3: =IFERROR(VLOOKUP(A3,'Price List SE'!$A$2:$D$93217,2,0),"Enter product code") -> Enter product code | C3: =IFERROR(VLOOKUP(A3,'Price List SE'!$A$2:$D$88096,3,0),"") | D3: =IFERROR(VLOOKUP(A3,'Price List SE'!$A$2:$D$93217,4,0),"")
B4: =IFERROR(VLOOKUP(A4,'Price List SE'!$A$2:$D$93217,2,0),"Enter product code") -> Enter product code | C4: =IFERROR(VLOOKUP(A4,'Price List SE'!$A$2:$D$88096,3,0),"") | D4: =IFERROR(VLOOKUP(A4,'Price List SE'!$A$2:$D$93217,4,0),"")
B5: =IFERROR(VLOOKUP(A5,'Price List SE'!$A$2:$D$93217,2,0),"Enter product code") -> Enter product code | C5: =IFERROR(VLOOKUP(A5,'Price List SE'!$A$2:$D$88096,3,0),"") | D5: =IFERROR(VLOOKUP(A5,'Price List SE'!$A$2:$D$93217,4,0),"")
B6: =IFERROR(VLOOKUP(A6,'Price List SE'!$A$2:$D$93217,2,0),"Enter product code") -> Enter product code | C6: =IFERROR(VLOOKUP(A6,'Price List SE'!$A$2:$D$88096,3,0),"") | D6: =IFERROR(VLOOKUP(A6,'Price List SE'!$A$2:$D$93217,4,0),"")
B7: =IFERROR(VLOOKUP(A7,'Price List SE'!$A$2:$D$93217,2,0),"Enter product code") -> Enter product code | C7: =IFERROR(VLOOKUP(A7,'Price List SE'!$A$2:$D$88096,3,0),"") | D7: =IFERROR(VLOOKUP(A7,'Price List SE'!$A$2:$D$93217,4,0),"")
B8: =IFERROR(VLOOKUP(A8,'Price List SE'!$A$2:$D$93217,2,0),"Enter product code") -> Enter product code | C8: =IFERROR(VLOOKUP(A8,'Price List SE'!$A$2:$D$88096,3,0),"") | D8: =IFERROR(VLOOKUP(A8,'Price List SE'!$A$2:$D$93217,4,0),"")
B9: =IFERROR(VLOOKUP(A9,'Price List SE'!$A$2:$D$93217,2,0),"Enter product code") -> Enter product code | C9: =IFERROR(VLOOKUP(A9,'Price List SE'!$A$2:$D$88096,3,0),"") | D9: =IFERROR(VLOOKUP(A9,'Price List SE'!$A$2:$D$93217,4,0),"")
B10: =IFERROR(VLOOKUP(A10,'Price List SE'!$A$2:$D$93217,2,0),"Enter product code") -> Enter product code | C10: =IFERROR(VLOOKUP(A10,'Price List SE'!$A$2:$D$88096,3,0),"") | D10: =IFERROR(VLOOKUP(A10,'Price List SE'!$A$2:$D$93217,4,0),"")
B11: =IFERROR(VLOOKUP(A11,'Price List SE'!$A$2:$D$93217,2,0),"Enter product code") -> Enter product code | C11: =IFERROR(VLOOKUP(A11,'Price List SE'!$A$2:$D$88096,3,0),"") | D11: =IFERROR(VLOOKUP(A11,'Price List SE'!$A$2:$D$93217,4,0),"")
B12: =IFERROR(VLOOKUP(A12,'Price List SE'!$A$2:$D$93217,2,0),"Enter product code") -> Enter product code | C12: =IFERROR(VLOOKUP(A12,'Price List SE'!$A$2:$D$88096,3,0),"") | D12: =IFERROR(VLOOKUP(A12,'Price List SE'!$A$2:$D$93217,4,0),"")
B13: =IFERROR(VLOOKUP(A13,'Price List SE'!$A$2:$D$93217,2,0),"Enter product code") -> Enter product code | C13: =IFERROR(VLOOKUP(A13,'Price List SE'!$A$2:$D$88096,3,0),"") | D13: =IFERROR(VLOOKUP(A13,'Price List SE'!$A$2:$D$93217,4,0),"")
... B50: =IFERROR(VLOOKUP(A50,'Price List SE'!$A$2:$D$93217,2,0),"Enter product code") -> Enter product code | C50: =IFERROR(VLOOKUP(A50,'Price List SE'!$A$2:$D$88096,3,0),"") | D50: =IFERROR(VLOOKUP(A50,'Price List SE'!$A$2:$D$93217,4,0),"")

Sheet Price List SE
A1: Nr kat | B1: Opis
A2: 105205 | B2: PMCtendo DD4.10/122/230-480V | C2: 7572.72
A3: 105219 | B3: PMCtendo DD4.01/122/230-480V | C3: 5924.31
A4: 105248 | B4: PMCtendo DD4.03/122/230-480V | C4: 6005.49
A5: 105266 | B5: PMCtendo DD4.06/117/230-480V | C5: 6453.54
A6: 1106100 | B6: PMCtendo DD4 spare part BGR connectors | C6: 360.71
A7: 1802620 | B7: Cable Can PMCLink>PMCLink:L=2,0m | C7: 7.64
A8: 1802949 | B8: Cable interface PC RS232>DD4/primo Drive | C8: 55.43
A9: 1803117 | B9: Cable Can PMCLink>PMCLink:L=0,7m | C9: 47.61
A10: 1803136 | B10: Cable Can PMCLink>PMCLink:L=0,25m | C10: 36.63
A11: 1S000003 | B11: PES test lead 4mm-bk | C11: 13.96
A12: 1S000004 | B12: PES test lead 4mm-rd | C12: 13.96
A13: 1S000005 | B13: PES test lead 4mm-bu | C13: 13.96
A14: 1S000006 | B14: PES test lead 4mm p-bk | C14: 17.94
A15: 1S000007 | B15: PES test lead 4mm p-rd | C15: 17.94
A16: 1S000008 | B16: PES test lead 4mm p-bu | C16: 17.94
A17: 1S000009 | B17: PES actuator board ec en | C17: 809.32
A18: 261905 | B18: RT-Licence PVIS OPC-Srv f.PMI, PtoP | C18: 129.2
A19: 261905G | B19: Project-Licence PVIS OPC-Srv f.PMI, PtoP | C19: 1939.76
A20: 261906 | B20: RT-Licence PVIS OPC-Srv f.PMI, 8 devices | C20: 404.14
A21: 261906G | B21: Project-Licence PVIS OPC-Srv f.PMI, 8 Co | C21: 6061.92
A22: 261907 | B22: RT-Licence PVIS OPC-Srv f. PC, PtoP | C22: 565.74
A23: 261907G | B23: Project-Licence PVIS OPC-Srv f. PC, PtoP | C23: 8486.55
A24: 261908 | B24: RT-Licence PVIS OPC-Srv f. PC, multiple | C24: 1131.65
A25: 261908G | B25: Project-Licence PVIS OPC-Srv f. PC, unli | C25: 16973.08
A26: 261910 | B26: PSS Upload-/Downloadtool f. PMIvisu/open | C26: 103.66
A27: 265010 | B27: Zenon Operator Dev 1024 | C27: 3379.68
A28: 265020 | B28: Zenon Operator 7.20 Dev 1024 | C28: 3379.68
A29: 265210 | B29: Zenon Operator RT PMI | C29: 675.94
A30: 265211 | B30: Zenon Operator RT PC 1024 | C30: 1313.21
A31: 265220 | B31: Zenon Operator 7.20 RT PMI | C31: 675.94
A32: 265240 | B32: Zenon Operator 7.20 RT PC 1024 | C32: 1313.21
A33: 265351 | B33: PASvisu RT Clients 1 | C33: 113.38
A34: 265352 | B34: PASvisu RT Clients 1 PMI | C34: 113.38
A35: 265361 | B35: PASvisu RT Logging PC | C35: 100.78
A36: 265362 | B36: PASvisu RT Logging PMI | C36: 62.99
A37: 265411 | B37: PASvisu RT Variables 150 PC | C37: 403.11
... A57: 269701 | B57: seal for PMIvisu, PMIopen, PMImicro | C57: 20.94
A58: 2A000002 | B58: PNOZ yh1 2DI 24VDC | C58: 84.51
A59: 2A000004 | B59: PNOZ yi1 4DI | C59: 102.99
...
